<?xml version="1.0" ?>
<!-- =================================================================================== -->
<!-- |    This document was autogenerated by xacro from slim.urdf.xacro                | -->
<!-- |    EDITING THIS FILE BY HAND IS NOT RECOMMENDED                                 | -->
<!-- =================================================================================== -->
<robot name="slim" xmlns:xacro="http://www.ros.org/wiki/xacro">
  <link name="base_link"/>
  <joint name="fixed" type="fixed">
    <parent link="base_link"/>
    <child link="lift_base"/>
  </joint>
  <link name="lift_base">
    <visual>
      <geometry>
        <box size="1.3 0.2 0.01"/>
      </geometry>
      <material name="LightGrey"/>
    </visual>
  </link>
  <gazebo reference="lift_base">
    <material>Gazebo/LightGrey</material>
  </gazebo>
  <joint name="lift_base_joint" type="fixed">
    <parent link="lift_base"/>
    <child link="fl_lift_rod"/>
  </joint>
  <link name="fl_lift_rod">
    <visual>
      <origin rpy="0 0 0" xyz="0.55 0.07 0.3"/>
      <geometry>
        <cylinder length="0.6" radius="0.01"/>
      </geometry>
      <material name="LightGrey"/>
    </visual>
  </link>
  <joint name="fl_lift_joint" type="prismatic">
    <axis xyz="0 0 1"/>
    <parent link="fl_lift_rod"/>
    <child link="slide_rail_base"/>
    <limit effort="1000.0" lower="0" upper="0.5" velocity="0.1"/>
  </joint>
  <link name="fr_lift_rod">
    <visual>
      <origin rpy="0 0 0" xyz="-0.55 0.07 0.3"/>
      <geometry>
        <cylinder length="0.6" radius="0.01"/>
      </geometry>
      <material name="LightGrey"/>
    </visual>
  </link>
  <joint name="fr_lift_joint" type="fixed">
    <parent link="lift_base"/>
    <child link="fr_lift_rod"/>
  </joint>
  <link name="bl_lift_rod">
    <visual>
      <origin rpy="0 0 0" xyz="0.55 -0.07 0.3"/>
      <geometry>
        <cylinder length="0.6" radius="0.01"/>
      </geometry>
      <material name="LightGrey"/>
    </visual>
  </link>
  <joint name="bl_lift_joint" type="fixed">
    <parent link="lift_base"/>
    <child link="bl_lift_rod"/>
  </joint>
  <link name="br_lift_rod">
    <visual>
      <origin rpy="0 0 0" xyz="-0.55 -0.07 0.3"/>
      <geometry>
        <cylinder length="0.6" radius="0.01"/>
      </geometry>
      <material name="LightGrey"/>
    </visual>
  </link>
  <joint name="br_lift_joint" type="fixed">
    <parent link="lift_base"/>
    <child link="br_lift_rod"/>
  </joint>
  <link name="l_lift_rod_cap">
    <visual>
      <origin xyz="0.55 0 0.6"/>
      <geometry>
        <box size="0.05 0.2 0.01"/>
      </geometry>
      <material name="LightGrey"/>
    </visual>
  </link>
  <joint name="l_lift_rod_cap_joint" type="fixed">
    <parent link="fl_lift_rod"/>
    <child link="l_lift_rod_cap"/>
  </joint>
  <link name="r_lift_rod_cap">
    <visual>
      <origin xyz="-0.55 0 0.6"/>
      <geometry>
        <box size="0.05 0.2 0.01"/>
      </geometry>
      <material name="LightGrey"/>
    </visual>
  </link>
  <joint name="r_lift_rod_cap_joint" type="fixed">
    <parent link="fr_lift_rod"/>
    <child link="r_lift_rod_cap"/>
  </joint>
  <link name="slide_rail_base">
    <visual>
      <origin xyz="0 0 0.01"/>
      <geometry>
        <box size="1.2 0.2 0.01"/>
      </geometry>
      <material name="LightGrey"/>
    </visual>
  </link>
  <gazebo reference="slide_rail_base">
    <material>Gazebo/LightGrey</material>
  </gazebo>
  <joint name="slide_rail_base_joint" type="prismatic">
    <axis xyz="1 0 0"/>
    <parent link="slide_rail_base"/>
    <child link="slide_rail"/>
    <limit effort="1000.0" lower="-0.4" upper="0.4" velocity="0.2"/>
  </joint>
  <link name="slide_rail">
    <visual>
      <geometry>
        <box size="0.18 0.18 0.01"/>
      </geometry>
      <material name="LightGrey"/>
      <origin xyz="0 0 0.02"/>
    </visual>
  </link>
  <joint name="slide_rail_joint" type="fixed">
    <parent link="slide_rail"/>
    <child link="arm_base_link"/>
  </joint>
  <material name="Black">
    <color rgba="0.0 0.0 0.0 1.0"/>
  </material>
  <material name="Blue">
    <color rgba="0.0 0.0 0.8 1.0"/>
  </material>
  <material name="Green">
    <color rgba="0.0 0.8 0.0 1.0"/>
  </material>
  <material name="Grey">
    <color rgba="0.2 0.2 0.2 1.0"/>
  </material>
  <material name="LightGrey">
    <color rgba="0.6 0.6 0.6 1.0"/>
  </material>
  <material name="Orange">
    <color rgba="1.0 0.423529411765 0.0392156862745 1.0"/>
  </material>
  <material name="Brown">
    <color rgba="0.870588235294 0.811764705882 0.764705882353 1.0"/>
  </material>
  <material name="Red">
    <color rgba="0.8 0.0 0.0 1.0"/>
  </material>
  <material name="White">
    <color rgba="1.0 1.0 1.0 1.0"/>
  </material>
  <link name="arm_base_link">
    <inertial>
      <origin xyz="0 0 0"/>
      <mass value="1.0"/>
      <inertia ixx="1.0" ixy="0.0" ixz="0.0" iyy="100.0" iyz="0.0" izz="1.0"/>
    </inertial>
    <visual>
      <origin rpy="1.570795 0 0" xyz="0 0 0"/>
      <!-- rotate PI/2 -->
      <geometry>
        <mesh filename="package://clam_description/stl/base_link.STL" scale="0.001 0.001 0.001"/>
      </geometry>
      <material name="Grey"/>
    </visual>
    <collision>
      <origin rpy="1.570795 0 0" xyz="0 0 0"/>
      <!-- rotate PI/2 -->
      <geometry>
        <mesh filename="package://clam_description/stl/base_link_simple.STL" scale="0.001 0.001 0.001"/>
      </geometry>
    </collision>
  </link>
  <gazebo reference="arm_base_link">
    <material>Gazebo/Grey</material>
  </gazebo>
  <joint name="shoulder_pan_joint" type="revolute">
    <parent link="arm_base_link"/>
    <child link="shoulder_pan_link"/>
    <origin rpy="0 1.570795 0.0" xyz="0 0 0.05"/>
    <axis xyz="-1 0 0"/>
    <limit effort="300" lower="-2.61799387799" upper="1.98394848567" velocity="1"/>
    <dynamics damping="50" friction="1"/>
  </joint>
  <link name="shoulder_pan_link">
    <inertial>
      <origin xyz="0 0 0"/>
      <mass value="1.0"/>
      <inertia ixx="1.0" ixy="0.0" ixz="0.0" iyy="100.0" iyz="0.0" izz="1.0"/>
    </inertial>
    <visual>
      <origin rpy="0 0 1.570795" xyz="0 0 0"/>
      <geometry>
        <mesh filename="package://clam_description/stl/shoulder_pan_link.STL" scale="0.001 0.001 0.001"/>
      </geometry>
      <material name="Orange"/>
    </visual>
    <collision>
      <origin rpy="0 0 1.570795" xyz="0 0 0"/>
      <geometry>
        <mesh filename="package://clam_description/stl/shoulder_pan_link_simple.STL" scale="0.001 0.001 0.001"/>
      </geometry>
    </collision>
  </link>
  <gazebo reference="shoulder_pan_link">
    <material>Gazebo/Orange</material>
  </gazebo>
  <joint name="shoulder_pitch_joint" type="revolute">
    <parent link="shoulder_pan_link"/>
    <child link="shoulder_pitch_link"/>
    <origin rpy="-1.570795 0 1.570795" xyz="-0.041 0.0021 0.0"/>
    <axis xyz="1 0 0"/>
    <limit effort="300" lower="-1.19962513147" upper="1.89994105047" velocity="1"/>
    <dynamics damping="50" friction="1"/>
  </joint>
  <link name="shoulder_pitch_link">
    <inertial>
      <origin xyz="-0.002 0 -0.000"/>
      <mass value="1.0"/>
      <inertia ixx="1.0" ixy="0.0" ixz="0.0" iyy="100.0" iyz="0.0" izz="1.0"/>
    </inertial>
    <visual>
      <origin rpy="1.570795 3.14159 1.570795" xyz="-0.002 0 -0.000"/>
      <geometry>
        <mesh filename="package://clam_description/stl/shoulder_pitch_link.STL" scale="0.001 0.001 0.001"/>
      </geometry>
      <material name="Grey"/>
    </visual>
    <collision>
      <origin rpy="1.570795 3.14159 1.570795" xyz="-0.002 0 -0.000"/>
      <geometry>
        <mesh filename="package://clam_description/stl/shoulder_pitch_link_simple.STL" scale="0.001 0.001 0.001"/>
      </geometry>
    </collision>
  </link>
  <gazebo reference="shoulder_pitch_link">
    <material>Gazebo/Grey</material>
  </gazebo>
  <joint name="elbow_roll_joint" type="revolute">
    <parent link="shoulder_pitch_link"/>
    <child link="elbow_roll_link"/>
    <origin rpy="3.14159 1.570795 0" xyz="-0.002 0 0.1206"/>
    <axis xyz="-1 0 0"/>
    <limit effort="300" lower="-2.61799387799" upper="0.705631162427" velocity="1"/>
    <dynamics damping="50" friction="1"/>
  </joint>
  <link name="elbow_roll_link">
    <inertial>
      <origin xyz="-0.035 0.0 0.0"/>
      <mass value="1.0"/>
      <inertia ixx="1.0" ixy="0.0" ixz="0.0" iyy="100.0" iyz="0.0" izz="1.0"/>
    </inertial>
    <visual>
      <origin rpy="3.14159 1.570795 1.570795" xyz="-0.035 0.0 0.0"/>
      <geometry>
        <mesh filename="package://clam_description/stl/elbow_roll_link.STL" scale="0.001 0.001 0.001"/>
      </geometry>
      <material name="Black"/>
    </visual>
    <collision>
      <origin rpy="3.14159 1.570795 1.570795" xyz="-0.035 0.0 0.0"/>
      <geometry>
        <mesh filename="package://clam_description/stl/elbow_roll_link_simple.STL" scale="0.001 0.001 0.001"/>
      </geometry>
    </collision>
  </link>
  <gazebo reference="elbow_roll_link">
    <material>Gazebo/Black</material>
  </gazebo>
  <joint name="elbow_pitch_joint" type="revolute">
    <parent link="elbow_roll_link"/>
    <child link="elbow_pitch_link"/>
    <origin rpy="0.055 1.570795 0" xyz="-0.035 0 0.0"/>
    <axis xyz="1 0 0"/>
    <limit effort="300" lower="-1.5953400194" upper="1.93281579274" velocity="1"/>
    <dynamics damping="50" friction="1"/>
  </joint>
  <link name="elbow_pitch_link">
    <inertial>
      <origin xyz="0.0 0 0"/>
      <mass value="1.0"/>
      <inertia ixx="1.0" ixy="0.0" ixz="0.0" iyy="100.0" iyz="0.0" izz="1.0"/>
    </inertial>
    <visual>
      <origin rpy="1.570795 0 4.712385" xyz="0.0 0 0"/>
      <geometry>
        <mesh filename="package://clam_description/stl/elbow_pitch_link.STL" scale="0.001 0.001 0.001"/>
      </geometry>
      <material name="Orange"/>
    </visual>
    <collision>
      <origin rpy="1.570795 0 4.712385" xyz="0.0 0 0"/>
      <geometry>
        <mesh filename="package://clam_description/stl/elbow_pitch_link_simple.STL" scale="0.001 0.001 0.001"/>
      </geometry>
    </collision>
  </link>
  <gazebo reference="elbow_pitch_link">
    <material>Gazebo/Orange</material>
  </gazebo>
  <joint name="wrist_roll_joint" type="revolute">
    <parent link="elbow_pitch_link"/>
    <child link="wrist_roll_link"/>
    <origin rpy="0 1.570795 3.14159" xyz="0.0 0.0081 -.248"/>
    <axis xyz="1 0 0"/>
    <limit effort="300" lower="-2.61799387799" upper="2.6128806087" velocity="1"/>
    <dynamics damping="50" friction="1"/>
  </joint>
  <link name="wrist_roll_link">
    <inertial>
      <origin xyz="0 0 0"/>
      <mass value="1.0"/>
      <inertia ixx="1.0" ixy="0.0" ixz="0.0" iyy="100.0" iyz="0.0" izz="1.0"/>
    </inertial>
    <visual>
      <origin rpy="0 1.570795 1.570795" xyz="0 0 0"/>
      <geometry>
        <mesh filename="package://clam_description/stl/wrist_roll_link.STL" scale="0.001 0.001 0.001"/>
      </geometry>
      <material name="Black"/>
    </visual>
    <collision>
      <origin rpy="0 1.570795 1.570795" xyz="0 0 0"/>
      <geometry>
        <mesh filename="package://clam_description/stl/wrist_roll_link_simple.STL" scale="0.001 0.001 0.001"/>
      </geometry>
    </collision>
  </link>
  <gazebo reference="wrist_roll_link">
    <material>Gazebo/Black</material>
  </gazebo>
  <joint name="wrist_pitch_joint" type="revolute">
    <parent link="wrist_roll_link"/>
    <child link="wrist_pitch_link"/>
    <origin rpy="0 1.570795 0" xyz="0.0 0.0 0.0001"/>
    <axis xyz="1 0 0"/>
    <limit effort="300" lower="-1.5953400194" upper="1.98394848567" velocity="1"/>
    <dynamics damping="50" friction="1"/>
  </joint>
  <link name="wrist_pitch_link">
    <inertial>
      <origin xyz="0 0 0"/>
      <mass value="1.0"/>
      <inertia ixx="1.0" ixy="0.0" ixz="0.0" iyy="100.0" iyz="0.0" izz="1.0"/>
    </inertial>
    <visual>
      <origin rpy="3.14159 -1.570795 0" xyz="0 0 0"/>
      <geometry>
        <mesh filename="package://clam_description/stl/wrist_pitch_link.STL" scale="0.001 0.001 0.001"/>
      </geometry>
      <material name="Grey"/>
    </visual>
    <collision>
      <origin rpy="3.14159 -1.570795 0" xyz="0 0 0"/>
      <geometry>
        <mesh filename="package://clam_description/stl/wrist_pitch_link_simple.STL" scale="0.001 0.001 0.001"/>
      </geometry>
    </collision>
  </link>
  <gazebo reference="wrist_pitch_link">
    <material>Gazebo/Grey</material>
  </gazebo>
  <joint name="gripper_roll_joint" type="revolute">
    <parent link="wrist_pitch_link"/>
    <child link="gripper_roll_link"/>
    <origin rpy="4.712385 -1.570795 0" xyz="0 0 0.080"/>
    <axis xyz="1 0 0"/>
    <limit effort="300" lower="-2.61799387799" upper="2.6128806087" velocity="1"/>
    <dynamics damping="50" friction="1"/>
  </joint>
  <link name="gripper_roll_link">
    <inertial>
      <origin xyz="0 0 0"/>
      <mass value="1.0"/>
      <inertia ixx="1.0" ixy="0.0" ixz="0.0" iyy="100.0" iyz="0.0" izz="1.0"/>
    </inertial>
    <visual>
      <origin rpy="0 0 0" xyz="0 0 0"/>
      <geometry>
        <mesh filename="package://clam_description/stl/gripper_roll_link.STL" scale="0.001 0.001 0.001"/>
      </geometry>
      <material name="Orange"/>
    </visual>
    <collision>
      <origin rpy="0 0 0" xyz="0 0 0"/>
      <geometry>
        <mesh filename="package://clam_description/stl/gripper_roll_link.STL" scale="0.001 0.001 0.001"/>
      </geometry>
    </collision>
  </link>
  <gazebo reference="gripper_roll_link">
    <material>Gazebo/Orange</material>
  </gazebo>
  <joint name="gripper_finger_joint" type="revolute">
    <parent link="gripper_roll_link"/>
    <child link="gripper_finger_link"/>
    <origin rpy="3.2672536 1.570795 0.603534345556" xyz="0.026 .017 0"/>
    <axis xyz="1 0 0"/>
    <limit effort="300" lower="-0.925023722222" upper="0.0" velocity="1"/>
    <dynamics damping="50" friction="1"/>
  </joint>
  <link name="gripper_finger_link">
    <inertial>
      <origin xyz="0 0 0"/>
      <mass value="1.0"/>
      <inertia ixx="1.0" ixy="0.0" ixz="0.0" iyy="100.0" iyz="0.0" izz="1.0"/>
    </inertial>
    <visual>
      <origin rpy="0 0 3.14159" xyz="0 0 0"/>
      <geometry>
        <mesh filename="package://clam_description/stl/l_gripper_aft_link.STL" scale="1 1 1"/>
      </geometry>
      <material name="Grey"/>
    </visual>
  </link>
  <gazebo reference="l_gripper_aft_link">
    <material>Gazebo/Grey</material>
  </gazebo>
  <joint name="r_gripper_aft_joint" type="revolute">
    <parent link="gripper_roll_link"/>
    <child link="r_gripper_aft_link"/>
    <origin rpy="4.22543855 1.570795 0.603534345556" xyz="0.026 -0.011  0"/>
    <axis xyz="1 0 0"/>
    <limit effort="300" lower="-3.14" upper="3.14" velocity="1"/>
    <mimic joint="gripper_finger_joint" multiplier="-1.0" offset="0.0"/>
    <dynamics damping="50" friction="1"/>
  </joint>
  <link name="r_gripper_aft_link">
    <inertial>
      <origin xyz="0 0 0"/>
      <mass value="1.0"/>
      <inertia ixx="1.0" ixy="0.0" ixz="0.0" iyy="100.0" iyz="0.0" izz="1.0"/>
    </inertial>
    <visual>
      <origin rpy="0 0 3.14159" xyz="0 0 0"/>
      <geometry>
        <mesh filename="package://clam_description/stl/r_gripper_aft_link.STL" scale="1 1 1"/>
      </geometry>
      <material name="Grey"/>
    </visual>
  </link>
  <gazebo reference="r_gripper_aft_link">
    <material>Gazebo/Grey</material>
  </gazebo>
  <joint name="l_gripper_fwd_joint" type="revolute">
    <parent link="gripper_roll_link"/>
    <child link="l_gripper_fwd_link"/>
    <origin rpy="3.2672536 1.570795 3.74512434556" xyz="0.05 0.008 0.007"/>
    <axis xyz="1 0 0"/>
    <limit effort="300" lower="0" upper="1.57" velocity="1"/>
    <mimic joint="gripper_finger_joint" multiplier="1.0" offset="0.0"/>
    <dynamics damping="50" friction="1"/>
  </joint>
  <link name="l_gripper_fwd_link">
    <inertial>
      <origin xyz="0 0 0"/>
      <mass value="1.0"/>
      <inertia ixx="1.0" ixy="0.0" ixz="0.0" iyy="100.0" iyz="0.0" izz="1.0"/>
    </inertial>
    <visual>
      <origin rpy="0 0 3.14159" xyz="0 0 0"/>
      <geometry>
        <mesh filename="package://clam_description/stl/l_gripper_fwd_link.STL" scale="1 1 1"/>
      </geometry>
      <material name="Grey"/>
    </visual>
  </link>
  <gazebo reference="l_gripper_fwd_link">
    <material>Gazebo/Grey</material>
  </gazebo>
  <joint name="r_gripper_fwd_joint" type="revolute">
    <parent link="gripper_roll_link"/>
    <child link="r_gripper_fwd_link"/>
    <origin rpy="3.0159264 1.570795 2.53805565444" xyz="0.05 -0.0014 0.007"/>
    <axis xyz="1 0 0"/>
    <limit effort="300" lower="-1.57" upper="0" velocity="1"/>
    <mimic joint="gripper_finger_joint" multiplier="-1.0" offset="0.0"/>
    <dynamics damping="50" friction="1"/>
  </joint>
  <link name="r_gripper_fwd_link">
    <inertial>
      <origin xyz="0 0 0"/>
      <mass value="1.0"/>
      <inertia ixx="1.0" ixy="0.0" ixz="0.0" iyy="100.0" iyz="0.0" izz="1.0"/>
    </inertial>
    <visual>
      <origin rpy="0 0 3.14159" xyz="0 0 0"/>
      <geometry>
        <mesh filename="package://clam_description/stl/r_gripper_fwd_link.STL" scale="1 1 1"/>
      </geometry>
      <material name="Grey"/>
    </visual>
  </link>
  <gazebo reference="r_gripper_fwd_link">
    <material>Gazebo/Grey</material>
  </gazebo>
  <joint name="gripper_finger_pincher_joint" type="revolute">
    <parent link="gripper_finger_link"/>
    <child link="l_gripper_pincher_link"/>
    <origin rpy="2.55812692389 0 0" xyz="-0.0032 0 -0.0508"/>
    <axis xyz="1 0 0"/>
    <limit effort="300" lower="-1.57" upper="1.57" velocity="1"/>
    <mimic joint="gripper_finger_joint" multiplier="-1.0" offset="0.0"/>
    <dynamics damping="50" friction="1"/>
  </joint>
  <link name="l_gripper_pincher_link">
    <inertial>
      <origin xyz="0 0 0"/>
      <mass value="1.0"/>
      <inertia ixx="1.0" ixy="0.0" ixz="0.0" iyy="100.0" iyz="0.0" izz="1.0"/>
    </inertial>
    <visual>
      <origin rpy="0 0 3.14159" xyz="0 0 0"/>
      <geometry>
        <mesh filename="package://clam_description/stl/l_gripper_pincher.STL" scale="1 1 1"/>
      </geometry>
      <material name="Black"/>
    </visual>
  </link>
  <gazebo reference="l_gripper_pincher_link">
    <material>Gazebo/Black</material>
  </gazebo>
  <joint name="r_gripper_aft_pincher_joint" type="revolute">
    <parent link="r_gripper_aft_link"/>
    <child link="r_gripper_pincher_link"/>
    <origin rpy="-0.583463076111 3.14159 0" xyz="0 0 -0.0508"/>
    <axis xyz="1 0 0"/>
    <limit effort="300" lower="0" upper="1.57" velocity="1"/>
    <mimic joint="gripper_finger_joint" multiplier="-1.0" offset="0.0"/>
    <dynamics damping="50" friction="1"/>
  </joint>
  <link name="r_gripper_pincher_link">
    <inertial>
      <origin xyz="0 0 0"/>
      <mass value="1.0"/>
      <inertia ixx="1.0" ixy="0.0" ixz="0.0" iyy="100.0" iyz="0.0" izz="1.0"/>
    </inertial>
    <visual>
      <origin rpy="0 0 3.14159" xyz="0 0 0"/>
      <geometry>
        <mesh filename="package://clam_description/stl/r_gripper_pincher.STL" scale="1 1 1"/>
      </geometry>
      <material name="Black"/>
    </visual>
  </link>
  <gazebo reference="r_gripper_pincher_link">
    <material>Gazebo/Black</material>
  </gazebo>
  <transmission name="tran1">
    <type>transmission_interface/SimpleTransmission</type>
    <joint name="shoulder_pan_joint">
      <hardwareInterface>EffortJointInterface</hardwareInterface>
    </joint>
    <actuator name="motor1">
      <hardwareInterface>EffortJointInterface</hardwareInterface>
      <mechanicalReduction>1</mechanicalReduction>
    </actuator>
  </transmission>
  <transmission name="tran1">
    <type>transmission_interface/SimpleTransmission</type>
    <joint name="shoulder_pitch_joint">
      <hardwareInterface>EffortJointInterface</hardwareInterface>
    </joint>
    <actuator name="motor1">
      <hardwareInterface>EffortJointInterface</hardwareInterface>
      <mechanicalReduction>1</mechanicalReduction>
    </actuator>
  </transmission>
  <transmission name="tran1">
    <type>transmission_interface/SimpleTransmission</type>
    <joint name="elbow_roll_joint">
      <hardwareInterface>EffortJointInterface</hardwareInterface>
    </joint>
    <actuator name="motor1">
      <hardwareInterface>EffortJointInterface</hardwareInterface>
      <mechanicalReduction>1</mechanicalReduction>
    </actuator>
  </transmission>
  <transmission name="tran1">
    <type>transmission_interface/SimpleTransmission</type>
    <joint name="elbow_pitch_joint">
      <hardwareInterface>EffortJointInterface</hardwareInterface>
    </joint>
    <actuator name="motor1">
      <hardwareInterface>EffortJointInterface</hardwareInterface>
      <mechanicalReduction>1</mechanicalReduction>
    </actuator>
  </transmission>
  <transmission name="tran1">
    <type>transmission_interface/SimpleTransmission</type>
    <joint name="wrist_roll_joint">
      <hardwareInterface>EffortJointInterface</hardwareInterface>
    </joint>
    <actuator name="motor1">
      <hardwareInterface>EffortJointInterface</hardwareInterface>
      <mechanicalReduction>1</mechanicalReduction>
    </actuator>
  </transmission>
  <transmission name="tran1">
    <type>transmission_interface/SimpleTransmission</type>
    <joint name="wrist_pitch_joint">
      <hardwareInterface>EffortJointInterface</hardwareInterface>
    </joint>
    <actuator name="motor1">
      <hardwareInterface>EffortJointInterface</hardwareInterface>
      <mechanicalReduction>1</mechanicalReduction>
    </actuator>
  </transmission>
  <transmission name="tran1">
    <type>transmission_interface/SimpleTransmission</type>
    <joint name="gripper_roll_joint">
      <hardwareInterface>EffortJointInterface</hardwareInterface>
    </joint>
    <actuator name="motor1">
      <hardwareInterface>EffortJointInterface</hardwareInterface>
      <mechanicalReduction>1</mechanicalReduction>
    </actuator>
  </transmission>
  <transmission name="tran1">
    <type>transmission_interface/SimpleTransmission</type>
    <joint name="gripper_finger_joint">
      <hardwareInterface>EffortJointInterface</hardwareInterface>
    </joint>
    <actuator name="motor1">
      <hardwareInterface>EffortJointInterface</hardwareInterface>
      <mechanicalReduction>1</mechanicalReduction>
    </actuator>
  </transmission>
  <gazebo>
    <plugin filename="libgazebo_ros_control.so" name="gazebo_ros_control">
      <robotNamespace>/clam</robotNamespace>
    </plugin>
  </gazebo>
</robot>

