<?xml version="1.0"?>
<robot xmlns:xacro="http://www.ros.org/wiki/xacro" name="slim">

  <xacro:include filename="$(find slim_description)/urdf/macros.xacro" />

  <link name="base_link" />

  <joint name="fixed" type="fixed">
    <parent link="base_link" />
    <child link="lift_base" />
  </joint>

  <link name="lift_base">
    <visual>
      <origin xyz="0 -0.25 0" />
      <geometry>
        <box size="1.3 0.8 0.01" />
      </geometry>
      <material name="Grey" />
    </visual>
    <collision>
      <origin xyz="0 -0.35 0" />
      <geometry>
        <box size="1.3 0.8 0.01" />
      </geometry>
    </collision>
    <inertial>
      <origin xyz="0 -0.35 0" />
      <mass value="5" />
      <box_inertia m="5" x="1.3" y="0.8" z="0.01" />
    </inertial>
  </link>
  <gazebo reference="lift_base">
    <material>Gazebo/Grey</material>
  </gazebo>
  
  <joint name="fl_frame_post_joint" type="fixed">
    <parent link="lift_base" />
    <child link="fl_frame_post" />
  </joint>

  <link name="fl_frame_post">
    <visual>
      <origin xyz="0.55 0.14 0.3" />
      <geometry>
        <box size="0.02 0.02 0.6" />
      </geometry>
      <material name="Grey" />
    </visual>
    <collision>
      <origin xyz="0.55 0.14 0.3" />
      <geometry>
        <box size="0.02 0.02 0.6" />
      </geometry>
    </collision>
    <inertial>
      <origin xyz="0.55 0.14 0.3" />
      <mass value="5" />
      <box_inertia m="5" x="0.02" y="0.02" z="0.6" />
    </inertial>
  </link>
  <gazebo reference="fl_frame_post">
    <material>Gazebo/Grey</material>
  </gazebo>

  <joint name="fr_frame_post_joint" type="fixed">
    <parent link="lift_base" />
    <child link="fr_frame_post" />
  </joint>

  <link name="fr_frame_post">
    <visual>
      <origin xyz="-0.55 0.14 0.3" />
      <geometry>
        <box size="0.02 0.02 0.6" />
      </geometry>
      <material name="Grey" />
    </visual>
    <collision>
      <origin xyz="-0.55 0.14 0.3" />
      <geometry>
        <box size="0.02 0.02 0.6" />
      </geometry>
    </collision>
    <inertial>
      <origin xyz="-0.55 0.14 0.3" />
      <mass value="5" />
      <box_inertia m="5" x="0.02" y="0.02" z="0.6" />
    </inertial>
  </link>
  <gazebo reference="fr_frame_post">
    <material>Gazebo/Grey</material>
  </gazebo>

  <joint name="bl_frame_post_joint" type="fixed">
    <parent link="lift_base" />
    <child link="bl_frame_post" />
  </joint>

  <link name="bl_frame_post">
    <visual>
      <origin xyz="0.55 -0.64 0.3" />
      <geometry>
        <box size="0.02 0.02 0.6" />
      </geometry>
      <material name="Grey" />
    </visual>
    <collision>
      <origin xyz="0.55 -0.64 0.3" />
      <geometry>
        <box size="0.02 0.02 0.6" />
      </geometry>
    </collision>
    <inertial>
      <origin xyz="0.55 -0.64 0.3" />
      <mass value="5" />
      <box_inertia m="5" x="0.02" y="0.02" z="0.6" />
    </inertial>
  </link>
  <gazebo reference="bl_frame_post">
    <material>Gazebo/Grey</material>
  </gazebo>

  <joint name="br_frame_post_joint" type="fixed">
    <parent link="lift_base" />
    <child link="br_frame_post" />
  </joint>

  <link name="br_frame_post">
    <visual>
      <origin xyz="-0.55 -0.64 0.3" />
      <geometry>
        <box size="0.02 0.02 0.6" />
      </geometry>
      <material name="Grey" />
    </visual>
    <collision>
      <origin xyz="-0.55 -0.64 0.3" />
      <geometry>
        <box size="0.02 0.02 0.6" />
      </geometry>
    </collision>
    <inertial>
      <origin xyz="-0.55 -0.64 0.3" />
      <mass value="5" />
      <box_inertia m="5" x="0.02" y="0.02" z="0.6" />
    </inertial>
  </link>
  <gazebo reference="br_frame_post">
    <material>Gazebo/Grey</material>
  </gazebo>

  <joint name="lift_base_joint" type="fixed">
    <parent link="lift_base" />
    <child link="fl_lift_rod" />
  </joint>

  <link name="fl_lift_rod">
    <visual>
      <origin xyz="0.55 0.07 0.3" rpy="0 0 0" />
      <geometry>
        <cylinder length="0.6" radius="0.01" />
      </geometry>
      <material name="Grey" />
    </visual>
    <collision>
      <origin xyz="0.55 0.07 0.3" rpy="0 0 0" />
      <geometry>
        <cylinder length="0.6" radius="0.01" />
      </geometry>
    </collision>
    <inertial>
      <mass value="5" />
      <cylinder_inertia m="5" r="0.01" h="0.6" />
    </inertial>
  </link>
  <gazebo reference="fl_lift_rod">
    <material>Gazebo/Grey</material>
  </gazebo>

  <joint name="fl_lift_joint" type="prismatic">
    <axis xyz="0 0 1" />
    <parent link="fl_lift_rod" />
    <child link="slide_rail_base" />
    <limit effort="1000.0" velocity="0.1" lower="0" upper="0.5" />
  </joint>

  <link name="fr_lift_rod">
    <visual>
      <origin xyz="-0.55 0.07 0.3" rpy="0 0 0" />
      <geometry>
        <cylinder length="0.6" radius="0.01" />
      </geometry>
      <material name="Grey" />
    </visual>
    <collision>
      <origin xyz="-0.55 0.07 0.3" rpy="0 0 0" />
      <geometry>
        <cylinder length="0.6" radius="0.01" />
      </geometry>
    </collision>
    <inertial>
      <mass value="5" />
      <cylinder_inertia m="5" r="0.01" h="0.6" />
    </inertial>
  </link>
  <gazebo reference="fr_lift_rod">
    <material>Gazebo/Grey</material>
  </gazebo>

  <joint name="fr_lift_joint" type="fixed">
    <parent link="lift_base" />
    <child link="fr_lift_rod" />
  </joint>

  <link name="bl_lift_rod">
    <visual>
      <origin xyz="0.55 -0.07 0.3" rpy="0 0 0" />
      <geometry>
        <cylinder length="0.6" radius="0.01" />
      </geometry>
      <material name="Grey" />
    </visual>
    <collision>
      <origin xyz="0.55 -0.07 0.3" rpy="0 0 0" />
      <geometry>
        <cylinder length="0.6" radius="0.01" />
      </geometry>
    </collision>
    <inertial>
      <mass value="5" />
      <cylinder_inertia m="5" r="0.01" h="0.6" />
    </inertial>
  </link>
  <gazebo reference="bl_lift_rod">
    <material>Gazebo/Grey</material>
  </gazebo>

  <joint name="bl_lift_joint" type="fixed">
    <parent link="lift_base" />
    <child link="bl_lift_rod" />
  </joint>

  <link name="br_lift_rod">
    <visual>
      <origin xyz="-0.55 -0.07 0.3" rpy="0 0 0" />
      <geometry>
        <cylinder length="0.6" radius="0.01" />
      </geometry>
      <material name="Grey" />
    </visual>
    <collision>
      <origin xyz="-0.55 -0.07 0.3" rpy="0 0 0" />
      <geometry>
        <cylinder length="0.6" radius="0.01" />
      </geometry>
    </collision>
    <inertial>
      <mass value="5" />
      <cylinder_inertia m="5" r="0.01" h="0.6" />
    </inertial>
  </link>
  <gazebo reference="br_lift_rod">
    <material>Gazebo/Grey</material>
  </gazebo>

  <joint name="br_lift_joint" type="fixed">
    <parent link="lift_base" />
    <child link="br_lift_rod" />
  </joint>

  <link name="back_frame">
    <visual>
      <origin xyz="0 -0.64 0.595" />
      <geometry>
        <box size="1.12 0.02 0.02" />
      </geometry>
      <material name="Grey" />
    </visual>
    <collision>
      <origin xyz="0 -0.64 0.595" />
      <geometry>
        <box size="1.12 0.02 0.02" />
      </geometry>
    </collision>
    <inertial>
      <origin xyz="0 -0.64 0.595" />
      <mass value="5" />
      <box_inertia m="5" x="1.12" y="0.02" z="0.02" />
    </inertial>
  </link>
  <gazebo reference="back_frame">
    <material>Gazebo/Grey</material>
  </gazebo>
  
  <joint name="back_frame_joint" type="fixed">
    <parent link="l_lift_rod_cap" />
    <child link="back_frame" />
  </joint>

  <link name="l_lift_rod_cap">
    <visual>
      <origin xyz="0.55 -0.25 0.6" />
      <geometry>
        <box size="0.05 0.8 0.01" />
      </geometry>
      <material name="Grey" />
    </visual>
    <collision>
      <origin xyz="0.55 0 0.6" />
      <geometry>
        <box size="0.05 0.2 0.01" />
      </geometry>
    </collision>
    <inertial>
      <mass value="5" />
      <box_inertia m="5" x="0.05" y="0.2" z="0.01" />
    </inertial>
  </link>
  <gazebo reference="l_lift_rod_cap">
    <material>Gazebo/Grey</material>
  </gazebo>

  <joint name="l_lift_rod_cap_joint" type="fixed">
    <parent link="fl_lift_rod" />
    <child link="l_lift_rod_cap" />
  </joint>

  <link name="r_lift_rod_cap">
    <visual>
      <origin xyz="-0.55 -0.25 0.6" />
      <geometry>
        <box size="0.05 0.8 0.01" />
      </geometry>
      <material name="Grey" />
    </visual>
    <collision>
      <origin xyz="-0.55 0 0.6" />
      <geometry>
        <box size="0.05 0.2 0.01" />
      </geometry>
    </collision>
    <inertial>
      <mass value="5" />
      <box_inertia m="5" x="0.05" y="0.8" z="0.01" />
    </inertial>
  </link>
  <gazebo reference="r_lift_rod_cap">
    <material>Gazebo/Grey</material>
  </gazebo>

  <joint name="r_lift_rod_cap_joint" type="fixed">
    <parent link="fr_lift_rod" />
    <child link="r_lift_rod_cap" />
  </joint>

  <link name="slide_rail_base">
    <visual>
      <origin xyz="0 0 0.01" />
      <geometry>
        <box size="1.2 0.2 0.01" />
      </geometry>
      <material name="Grey" />
    </visual>
    <collision>
      <origin xyz="0 0 0.01" />
      <geometry>
        <box size="1.2 0.2 0.01" />
      </geometry>
    </collision>
    <inertial>
      <mass value="5" />
      <box_inertia m="5" x="1.2" y="0.2" z="0.01" />
    </inertial>
  </link>
  <gazebo reference="slide_rail_base">
    <material>Gazebo/Grey</material>
  </gazebo>

  <joint name="slide_rail_base_joint" type="prismatic">
    <axis xyz="1 0 0" />
    <parent link="slide_rail_base" />
    <child link="slide_rail" />
    <limit effort="1000.0" velocity="0.2" lower="-0.4" upper="0.4" />
  </joint>

  <link name="slide_rail">
    <visual>
      <geometry>
        <box size="0.18 0.18 0.01" />
      </geometry>
      <material name="Grey" />
      <origin xyz="0 0 0.02" />
    </visual>
    <collision>
      <geometry>
        <box size="0.18 0.18 0.01" />
      </geometry>
      <origin xyz="0 0 0.02" />
    </collision>
    <inertial>
      <mass value="5" />
      <box_inertia m="5" x="0.18" y="0.18" z="0.01" />
    </inertial>
  </link>
  <gazebo reference="slide_rail">
    <material>Gazebo/Grey</material>
  </gazebo>

  <joint name="slide_rail_joint" type="fixed">
    <parent link="slide_rail" />
    <child link="arm_base_link" />
  </joint>

  <transmission name="fl_lift_trans">
    <type>transmission_interface/SimpleTransmission</type>
    <joint name="fl_lift_joint">
      <hardwareInterface>PositionJointInterface</hardwareInterface>
    </joint>
    <actuator name="fl_lift_motor">
      <hardwareInterface>PositionJointInterface</hardwareInterface>
      <mechanicalReduction>1</mechanicalReduction>
    </actuator>
  </transmission>
  <transmission name="slide_rail_base_trans">
    <type>transmission_interface/SimpleTransmission</type>
    <joint name="slide_rail_base_joint">
      <hardwareInterface>PositionJointInterface</hardwareInterface>
    </joint>
    <actuator name="slide_rail_base_motor">
      <hardwareInterface>PositionJointInterface</hardwareInterface>
      <mechanicalReduction>1</mechanicalReduction>
    </actuator>
  </transmission>

  <xacro:include filename="$(find clam_description)/urdf/clam.xacro" />

  <!-- ros_control plugin -->
  <gazebo>
    <plugin name="gazebo_ros_control" filename="libgazebo_ros_control.so">
      <robotNamespace>/slim</robotNamespace>
    </plugin>
  </gazebo>

</robot>
